<?xml version="1.0"?>
<robot name="franka_research_3">
  <material name="black">
    <color rgba="0 0 0 1"/>
  </material>

  <material name="blue">
    <color rgba="0 0 0.8 1"/>
  </material>

  <material name="blue_clear">
    <color rgba="0 0 0.8 0.5"/>
  </material>

  <material name="red_clear">
    <color rgba="0.8 0 0 0.5"/>
  </material>

  <material name="white">
    <color rgba="1 1 1 1"/>
  </material>

  <material name="link_col_1">
    <color rgba="0.8 0 0 .8"/>
  </material>

  <material name="link_col_2">
    <color rgba="0 0.8 0 .8"/>
  </material>

  <material name="link_col_3">
    <color rgba="0 0 0.8 .8"/>
  </material>

  <link name="world">
  </link>

  <link name="base_box">
    <visual>
      <geometry>
        <box size="0.2 0.12 0.1"/>
      </geometry>
      <origin xyz="0 0 0.05"/>
      <material name="white"/>
    </visual>
    <collision>
      <geometry>
        <box size="0.2 0.12 0.1"/>
      </geometry>
      <origin xyz="0 0 0.05"/>
    </collision>
  </link>
  <joint name="base_box_to_world" type="fixed">
    <parent link="world"/>
    <child link="base_box"/>
    <origin xyz="0 0 0"/>
  </joint>

  <link name="base_cyl">
    <visual>
      <geometry>
        <cylinder length="0.033" radius="0.06"/>
      </geometry>
      <origin xyz="0 0 0.0165"/>
      <material name="black"/>
    </visual>
    <collision>
      <geometry>
        <cylinder length="0.033" radius="0.065"/>
      </geometry>
      <origin xyz="0 0 0.0165"/>
    </collision>
  </link>
  <joint name="base_cyl_to_base_box" type="fixed">
    <parent link="base_box"/>
    <child link="base_cyl"/>
    <origin xyz="0.04 0 0.1"/>
  </joint>

  <link name="arm_link_1a">
    <visual>
      <geometry>
        <cylinder length="0.14" radius="0.06"/>
      </geometry>
      <origin xyz="0 0 0.07"/>
      <material name="link_col_1"/>
    </visual>
    <collision>
      <geometry>
        <cylinder length="0.14" radius="0.06"/>
      </geometry>
      <origin xyz="0 0 0.07"/>
    </collision>
  </link>
  <joint name="arm_link_1a_to_base_cyl" type="revolute">
    <parent link="base_cyl"/>
    <child link="arm_link_1a"/>
    <origin xyz="0 0 0.033"/>
    <axis xyz="0 0 1"/>
    <limit effort="1000.0" lower="-2.897247" upper="2.897247" velocity="2.617994"/>
  </joint>

  <link name="arm_link_1b">
    <visual>
      <geometry>
        <cylinder length="0.06" radius="0.06"/>
      </geometry>
      <origin xyz="0 -0.03 0" rpy="1.570796 0 0"/>
      <material name="link_col_1"/>
    </visual>
    <collision>
      <geometry>
        <cylinder length="0.06" radius="0.06"/>
      </geometry>
      <origin xyz="0 -0.03 0" rpy="1.570796 0 0"/>
    </collision>
  </link>
  <joint name="arm_link_1b_to_1a" type="fixed">
    <parent link="arm_link_1a"/>
    <child link="arm_link_1b"/>
    <origin xyz="0 0 0.2"/>
  </joint>

  <link name="arm_link_1c">
    <visual>
      <geometry>
        <sphere radius="0.06"/>
      </geometry>
      <material name="link_col_1"/>
    </visual>
    <collision>
      <geometry>
        <sphere radius="0.06"/>
      </geometry>
    </collision>
  </link>
  <joint name="arm_link_1c_to_1b" type="fixed">
    <parent link="arm_link_1b"/>
    <child link="arm_link_1c"/>
    <origin xyz="0 -0.06 0"/>
  </joint>


  <link name="arm_link_2b">
    <visual>
      <geometry>
        <cylinder length="0.06" radius="0.06"/>
      </geometry>
      <origin xyz="0 0.03 0" rpy="-1.570796 0 0"/>
      <material name="link_col_2"/>
    </visual>
    <collision>
      <geometry>
        <cylinder length="0.06" radius="0.06"/>
      </geometry>
      <origin xyz="0 0.03 0" rpy="-1.570796 0 0"/>
    </collision>
  </link>
  <joint name="arm_link_2b_to_1b" type="revolute">
    <parent link="arm_link_1b"/>
    <child link="arm_link_2b"/>
    <origin xyz="0 0 0"/>
    <axis xyz="0 1 0"/>
    <limit effort="1000.0" lower="-1.832596" upper="1.832596" velocity="2.617994"/>
  </joint>

  <link name="arm_link_2c">
    <visual>
      <geometry>
        <sphere radius="0.06"/>
      </geometry>
      <material name="link_col_2"/>
    </visual>
    <collision>
      <geometry>
        <sphere radius="0.06"/>
      </geometry>
    </collision>
  </link>
  <joint name="arm_link_2c_to_2b" type="fixed">
    <parent link="arm_link_2b"/>
    <child link="arm_link_2c"/>
    <origin xyz="0 0.06 0"/>
  </joint>

  <link name="arm_link_2a">
    <visual>
      <geometry>
        <cylinder length="0.14" radius="0.06"/>
      </geometry>
      <origin xyz="0 0 0.07"/>
      <material name="link_col_2"/>
    </visual>
    <collision>
      <geometry>
        <cylinder length="0.14" radius="0.06"/>
      </geometry>
      <origin xyz="0 0 0.07"/>
    </collision>
  </link>
  <joint name="arm_link_2a_to_2b" type="fixed">
    <parent link="arm_link_2b"/>
    <child link="arm_link_2a"/>
    <origin xyz="0 0 0.06"/>
  </joint>


  <link name="arm_link_3a">
    <visual>
      <geometry>
        <cylinder length="0.05" radius="0.06"/>
      </geometry>
      <origin xyz="0 0 0.025"/>
      <material name="link_col_3"/>
    </visual>
    <collision>
      <geometry>
        <cylinder length="0.05" radius="0.06"/>
      </geometry>
      <origin xyz="0 0 0.025"/>
    </collision>
  </link>
  <joint name="arm_link_3a_to_2a" type="revolute">
    <parent link="arm_link_2a"/>
    <child link="arm_link_3a"/>
    <origin xyz="0 0 0.14"/>
    <axis xyz="0 0 1"/>
    <limit effort="1000.0" lower="-2.897247" upper="2.897247" velocity="2.617994"/>
  </joint>

  <link name="arm_link_3c">
    <visual>
      <geometry>
        <sphere radius="0.06"/>
      </geometry>
      <material name="link_col_3"/>
    </visual>
    <collision>
      <geometry>
        <sphere radius="0.06"/>
      </geometry>
    </collision>
  </link>
  <joint name="arm_link_3c_to_3a" type="fixed">
    <parent link="arm_link_3a"/>
    <child link="arm_link_3c"/>
    <origin xyz="0 0 0.06"/>
  </joint>

  <link name="arm_link_3b">
    <visual>
      <geometry>
        <cylinder length="0.06" radius="0.06"/>
      </geometry>
      <origin xyz="0 0.03 0" rpy="-1.570796 0 0"/>
      <material name="link_col_3"/>
    </visual>
    <collision>
      <geometry>
        <cylinder length="0.06" radius="0.06"/>
      </geometry>
      <origin xyz="0 0.03 0" rpy="-1.570796 0 0"/>
    </collision>
  </link>
  <joint name="arm_link_3b_to_3a" type="fixed">
    <parent link="arm_link_3a"/>
    <child link="arm_link_3b"/>
    <origin xyz="0.082 0 0.116"/>
  </joint>

  <link name="arm_link_3d">
    <visual>
      <geometry>
        <cylinder radius="0.06" length="0.02"/>
      </geometry>
      <origin xyz="0 0.01 0" rpy="1.570796 0 0"/>
      <material name="black"/>
    </visual>
    <collision>
      <geometry>
        <cylinder radius="0.06" length="0.02"/>
      </geometry>
      <origin xyz="0 0.01 0" rpy="1.570796 0 0"/>
    </collision>
  </link>
  <joint name="arm_link_3d_to_3b" type="fixed">
    <parent link="arm_link_3b"/>
    <child link="arm_link_3d"/>
    <origin xyz="0 0.06 0"/>
  </joint>

  <link name="arm_link_3e">
    <visual>
      <geometry>
        <sphere radius="0.05"/>
      </geometry>
      <material name="link_col_3"/>
    </visual>
    <collision>
      <geometry>
        <sphere radius="0.05"/>
      </geometry>
    </collision>
  </link>
  <joint name="arm_link_3e_to_3b" type="fixed">
    <parent link="arm_link_3b"/>
    <child link="arm_link_3e"/>
    <origin xyz="0 0.06 0"/>
  </joint>

  <link name="arm_link_4b">
    <visual>
      <geometry>
        <cylinder length="0.06" radius="0.06"/>
      </geometry>
      <origin xyz="0 -0.03 0" rpy="1.570796 0 0"/>
      <material name="link_col_1"/>
    </visual>
    <collision>
      <geometry>
        <cylinder length="0.06" radius="0.06"/>
      </geometry>
      <origin xyz="0 -0.03 0" rpy="1.570796 0 0"/>
    </collision>
  </link>
  <joint name="arm_link_4b_to_3b" type="revolute">
    <parent link="arm_link_3b"/>
    <child link="arm_link_4b"/>
    <origin xyz="0 0 0" rpy="0 0 0"/>
    <axis xyz="0 1 0"/>
    <!--limit effort="1000.0" lower="-0.122173" upper="-3.071779" velocity="2.617994"/>
    (already set at -90) -->
    <limit effort="1000.0" lower="-1.448623" upper="1.500983" velocity="2.617994"/>
  </joint>

  <link name="arm_link_4a">
    <visual>
      <geometry>
        <cylinder length="0.05" radius="0.06"/>
      </geometry>
      <origin xyz="-0.025 0 0" rpy="0 -1.570796 0"/>
      <material name="link_col_1"/>
    </visual>
    <collision>
      <geometry>
        <cylinder length="0.05" radius="0.06"/>
      </geometry>
      <origin xyz="-0.025 0 0" rpy="0 -1.570796 0"/>
    </collision>
  </link>
  <joint name="arm_link_4a_to_4b" type="fixed">
    <parent link="arm_link_4b"/>
    <child link="arm_link_4a"/>
    <origin xyz="0.116 0 0.082" rpy="0 0 0"/>
  </joint>

  <link name="arm_link_4c">
    <visual>
      <geometry>
        <sphere radius="0.06"/>
      </geometry>
      <material name="link_col_1"/>
    </visual>
    <collision>
      <geometry>
        <sphere radius="0.06"/>
      </geometry>
    </collision>
  </link>
  <joint name="arm_link_4c_to_4a" type="fixed">
    <parent link="arm_link_4a"/>
    <child link="arm_link_4c"/>
    <origin xyz="-0.06 0 0"/>
  </joint>

  <link name="arm_link_4d">
    <visual>
      <geometry>
        <cylinder radius="0.06" length="0.02"/>
      </geometry>
      <origin xyz="0 -0.01 0" rpy="1.570796 0 0"/>
      <material name="black"/>
    </visual>
    <collision>
      <geometry>
        <cylinder radius="0.06" length="0.02"/>
      </geometry>
      <origin xyz="0 -0.01 0" rpy="1.570796 0 0"/>
    </collision>
  </link>
  <joint name="arm_link_4d_to_4b" type="fixed">
    <parent link="arm_link_4b"/>
    <child link="arm_link_4d"/>
    <origin xyz="0 -0.06 0"/>
  </joint>

  <link name="arm_link_4e">
    <visual>
      <geometry>
        <sphere radius="0.05"/>
      </geometry>
      <material name="link_col_1"/>
    </visual>
    <collision>
      <geometry>
        <sphere radius="0.05"/>
      </geometry>
    </collision>
  </link>
  <joint name="arm_link_4e_to_4b" type="fixed">
    <parent link="arm_link_4b"/>
    <child link="arm_link_4e"/>
    <origin xyz="0 -0.06 0"/>
  </joint>

  <link name="arm_link_5a">
    <visual>
      <geometry>
        <cylinder length="0.208" radius="0.06"/>
      </geometry>
      <origin xyz="0.104 0 0" rpy="0 -1.570796 0"/>
      <material name="link_col_2"/>
    </visual>
    <collision>
      <geometry>
        <cylinder length="0.208" radius="0.06"/>
      </geometry>
      <origin xyz="0.104 0 0" rpy="0 -1.570796 0"/>
    </collision>
  </link>
  <joint name="arm_link_5a_to_4a" type="revolute">
    <parent link="arm_link_4a"/>
    <child link="arm_link_5a"/>
    <origin xyz="0 0 0" rpy="0 0 0"/>
    <axis xyz="1 0 0"/>
    <limit effort="1000.0" lower="-2.879793" upper="2.879793" velocity="5.253441"/>
  </joint>

  <link name="arm_link_5b">
    <visual>
      <geometry>
        <cylinder radius="0.06" length="0.06"/>
      </geometry>
      <origin xyz="0 0.03 0" rpy="1.570796 0 0"/>
      <material name="link_col_2"/>
    </visual>
  </link>
  <joint name="arm_link_5b_to_5a" type="fixed">
    <parent link="arm_link_5a"/>
    <child link="arm_link_5b"/>
    <origin xyz="0.268 0 0" rpy="0 0 0"/>
  </joint>



  <!-- TO DO: Make 4d & 4e (styling) and arms and joints 5-7 -->

</robot>